Workbook

Sheet Direcții
A1: ID_direcție | B1: Nume_direcție | C1: Număr_angajați | D1: Nume_responsabil | E1: ID_angajat
A2: 1 | B2: Corpul de Control al Primarului General | C2: 23 | D2: Ciucu Ciprian | E2: =_xlfn.XLOOKUP(D2, Structură_conducere!B:B,Structură_conducere!A:A, "NU GASIT",0) -> 101
A3: 2 | B3: Direcția Generală Economică | C3: 84 | D3: Jugureanu Emanuela | E3: =_xlfn.XLOOKUP(D3, Structură_conducere!B:B,Structură_conducere!A:A, "NU GASIT",0) -> 109
A4: 3 | B4: Direcția Generală Investiții | C4: 74 | D4: Aflat Cătălin Sebastian | E4: =_xlfn.XLOOKUP(D4, Structură_conducere!B:B,Structură_conducere!A:A, "NU GASIT",0) -> 119
A5: 4 | B5: Direcția Generală Management Proiecte cu Finanțare Externă | C5: 48 | D5: Anca Gabriela | E5: =_xlfn.XLOOKUP(D5, Structură_conducere!B:B,Structură_conducere!A:A, "NU GASIT",0) -> 127
A6: 5 | B6: Direcția Generală Urbanism și Amenajarea Teritoriului | C6: 68 | D6: Damian Matei | E6: =_xlfn.XLOOKUP(D6, Structură_conducere!B:B,Structură_conducere!A:A, "NU GASIT",0) -> 132
A7: 6 | B7: Direcția Generală Administrație și Relații cu Cgmb | C7: 124 | D7: Dragomir Cezar Nicolae | E7: =_xlfn.XLOOKUP(D7, Structură_conducere!B:B,Structură_conducere!A:A, "NU GASIT",0) -> 138
A8: 7 | B8: Direcția Generală Servicii Publice | C8: 82 | D8: Ionescu Roxana | E8: =_xlfn.XLOOKUP(D8, Structură_conducere!B:B,Structură_conducere!A:A, "NU GASIT",0) -> 150
A9: 8 | B9: Direcția Generală Achiziții Publice | C9: 43 | D9: Ticu Tinel Speranțiu | E9: =_xlfn.XLOOKUP(D9, Structură_conducere!B:B,Structură_conducere!A:A, "NU GASIT",0) -> 159
A10: 9 | B10: Direcția Generală Situații de Urgență, Statistici și Strategii | C10: 73 | D10: Zoican Cătălin Ion | E10: =_xlfn.XLOOKUP(D10, Structură_conducere!B:B,Structură_conducere!A:A, "NU GASIT",0) -> 164
A11: 10 | B11: Direcția Generală Logistică | C11: 127 | D11: Davidoiu Eugen | E11: =_xlfn.XLOOKUP(D11, Structură_conducere!B:B,Structură_conducere!A:A, "NU GASIT",0) -> 170
A12: 11 | B12: Direcția Patrimoniu | C12: 61 | D12: Perșunaru Mariana | E12: =_xlfn.XLOOKUP(D12, Structură_conducere!B:B,Structură_conducere!A:A, "NU GASIT",0) -> 177
A13: 12 | B13: Direcția de Mediu | C13: 45 | D13: Chiriță Mihaela | E13: =_xlfn.XLOOKUP(D13, Structură_conducere!B:B,Structură_conducere!A:A, "NU GASIT",0) -> 182
... A29: 28 | B29: Direcția Monitorizare Recuperare debite / Creanțe | C29: 25 | D29: Mincă Liliana | E29: =_xlfn.XLOOKUP(D29, Structură_conducere!B:B,Structură_conducere!A:A, "NU GASIT",0) -> 223

Sheet Structură_conducere
A1: ID_angajat | B1: Nume_angajat | C1: Funcție | D1: Salariu | E1: Direcție | F1: ID_direcție
A2: 101 | B2: Ciucu Ciprian | C2: Primar General | D2: 24150 | E2: Corpul de Control al Primarului General | F2: 1
A3: 102 | B3: Vigheciu Adrian Nicolae | C3: Viceprimar | D3: 21735 | E3: Corpul de Control al Primarului General | F3: 1
A4: 104 | B4: Miu Andreea Mihaela | C4: Director de Cabinet | D4: 9596 | E4: Cabinet Primar General | F4: 1
A5: 105 | B5: Zamfir Georgiana | C5: Secretar General al Municipiului Bucuresti | D5: 20962 | E5: Secretar General | F5: 1
A6: 106 | B6: Grigoraș Daniela | C6: Director Executiv | D6: 20429 | E6: Corpul de Control al Primarului General | F6: 1
A7: 107 | B7: Ion Marin | C7: Șef Serviciu | D7: 15989 | E7: Serviciul Control Instituțional | F7: 1
A8: 108 | B8: Balea Silvana Gabriela | C8: Șef Serviciu | D8: 15989 | E8: Serviciul Controlul Gestionării și Utilizării Fondurilor | F8: 1
A9: 109 | B9: Jugureanu Emanuela | C9: Director General | D9: 20962 | E9: Direcţia Generală Economică | F9: 2
A10: 110 | B10: Marica Mirela | C10: Șef Serviciu | D10: 15989 | E10: Serviciul Financiar | F10: 2
A11: 111 | B11: Anasia-Oprițescu Roxana Elena | C11: Șef Birou | D11: 15101 | E11: Biroul Financiar Investiții | F11: 2
A12: 112 | B12: Stănuca Victor | C12: Șef Serviciu | D12: 15989 | E12: Serviciul Contabilitate | F12: 2
A13: 113 | B13: Călin Diana Ionela | C13: Șef Serviciu | D13: 15989 | E13: Serviciul Control Financiar Preventiv | F13: 2
... A124: 226 | B124: Petre Cristian Daniel | C124: Șef Serviciu | D124: 15989 | E124: Serviciul Euro - 2020 | F124: 24

Sheet Contracte 
A1: ID_contract | B1: Data_contract | C1: Parte_contractantă | D1: Valoare(lei) | E1: Obiect_contract | F1: Valoare(lei) | G1: Direcție_responsabilă | H1: ID_direcție
A2: 202 | B2: 45673 | C2: GLOB STAR TRAde SRL | D2: 42192 | E2: Contract achizitie publica de produse - SURSE de ALIMENTARE NEINTRERUPTIBILE (UPS) | F2: 42192 | G2: Direcția Generală Logistică | H2: =_xlfn.XLOOKUP(G2, Direcții!B:B,Direcții!A:A, "NU GASIT",0) -> 10
A3: 203 | B3: 45674 | C3: LIBRO EVENTS SRL | D3: 269400 | E3: Contract de prestare - servicii de curatenie a spatiilor administrate de Municipiul Bucuresti, prin Directia Admninistrativa | F3: 269400 | G3: Direcția Generală Logistică | H3: =_xlfn.XLOOKUP(G3, Direcții!B:B,Direcții!A:A, "NU GASIT",0) -> 10
A4: 204 | B4: 45688 | C4: COMPANIA NATIONALA POSTA ROMANA SA | D4: 200000 | E4: Contract subsecvent 1 - servicii postale si de curierat | F4: 200000 | G4: Direcția Generală Logistică | H4: =_xlfn.XLOOKUP(G4, Direcții!B:B,Direcții!A:A, "NU GASIT",0) -> 10
A5: 205 | B5: 45688 | C5: FIP CONSULTING SRL | D5: 1180000 | E5: Act aditional nr 2 la contract nr.208.10.05.2024 privind servicii de elaborare documentație tehnică studiu de fezabilitate, completat cu elementele specifice din documentația de avizare a lucrărilor de intervenții pentru obiectivul “Studii, documentații pt. lucrări străzi-Lărgire bd. Dimitrie Pompeiu cu extindere infrastructură de tramvai și străpungere bd. Barbu Văcărescu, construire drum de legătură între șos. Pipera, bd. Dimitrie Pompeiu | F5: 1180000 | G5: Direcția Generală Investiții | H5: =_xlfn.XLOOKUP(G5, Direcții!B:B,Direcții!A:A, "NU GASIT",0) -> 3
A6: 206 | B6: 45712 | C6: PRIME TELECOM S.R.L. | D6: 8640 | E6: Contract de achizitie publica avand ca obiect prestare Servicii de lnterconectare a sediilor PMB | F6: 8640 | G6: Direcția Generală Logistică | H6: =_xlfn.XLOOKUP(G6, Direcții!B:B,Direcții!A:A, "NU GASIT",0) -> 10
A7: 207 | B7: 45716 | C7: VODAFONE ROMANIA S.A. | D7: 15720 | E7: Prestare ”Servicii de conectare în rețeaua metropolitană și accesul la internet al PMB” | F7: 15720 | G7: Direcția Generală Logistică | H7: =_xlfn.XLOOKUP(G7, Direcții!B:B,Direcții!A:A, "NU GASIT",0) -> 10
A8: 208 | B8: 45719 | C8: CORES ELECTRONIC SRL | D8: 46000 | E8: Service post-garantie pentru sistemul CORPAGE implementat la C.I.D.R.C. | F8: 46000 | G8: Direcția Generală Logistică | H8: =_xlfn.XLOOKUP(G8, Direcții!B:B,Direcții!A:A, "NU GASIT",0) -> 10
A9: 209 | B9: 45729 | C9: Centrul Teritorial de Calcul Electronic S.A. | D9: 7680 | E9: Servicii de asistență tehnică și mentenanță aplicație legislativă | F9: 7680 | G9: Direcția Generală Logistică | H9: =_xlfn.XLOOKUP(G9, Direcții!B:B,Direcții!A:A, "NU GASIT",0) -> 10
A10: 210 | B10: 45741 | C10: Asocierea Alpha Bank România S.A., Banca Comercială Română S.A., BRD – Groupe Société Générale S.A și Raiffeisen Bank S.A. | D10: 2840000 | E10: Contract de servicii | F10: 2840000 | G10: Direcția Generală Economică | H10: =_xlfn.XLOOKUP(G10, Direcții!B:B,Direcții!A:A, "NU GASIT",0) -> 2
A11: 211 | B11: 45741 | C11: Fitch Ratings Ireland Limited spółka z ograniczoną odpowiedzialnością oddział w Polsce | D11: 195000 | E11: Contract servicii | F11: 195000 | G11: Direcția Generală Economică | H11: =_xlfn.XLOOKUP(G11, Direcții!B:B,Direcții!A:A, "NU GASIT",0) -> 2
A12: 212 | B12: 45769 | C12: Depozitarul Central S.A. | D12: 15534 | E12: Contract de servicii de depozitare si registru | F12: 15534 | G12: Direcția Generală Economică | H12: =_xlfn.XLOOKUP(G12, Direcții!B:B,Direcții!A:A, "NU GASIT",0) -> 2
A13: 213 | B13: 45783 | C13: MEDIA TEHNOCABLU SRL | D13: 63200 | E13: Furnizare ”Unități de Hrd Disk, dispozitive de stocare, memorie RAM” | F13: 63200 | G13: Direcția Generală Logistică | H13: =_xlfn.XLOOKUP(G13, Direcții!B:B,Direcții!A:A, "NU GASIT",0) -> 10
... A24: 227 | B24: 45911 | C24: ENERGY CONTROL SOLUTIONS SRL | D24: 675000 | E24: Servicii de proiectare și execuție lucrări de racordare la rețeaua electrică a locului de consum Primaria Sector 5, B-dul Regina Elisabeta, nr. 29-31, Sector 5, pentru obiectivul de investiții „Consolidare, reabilitare, extindere si restaurare fatada imobil B-dul Regina Elisabeta, nr. 29-31, Sector 5” | F24: 675000 | G24: Direcția Generală Investiții | H24: =_xlfn.XLOOKUP(G24, Direcții!B:B,Direcții!A:A, "NU GASIT",0) -> 3
F25: =MAX(F2:F24) -> 2840000

Sheet Achiziții_publice
A1: ID_achiziție | B1: Denumire_achiziție | C1: Obiectul_contractului | D1: Tip_contract | E1: Valoare(lei) | F1: Sursă_finanțare | G1: Direcția_inițiatoare | H1: ID_direcție
A2: 301 | B2: Carburant pentru autovehiculele din parcul auto al PMB | C2: Furnizate | D2: Furnizare - Acord cadru | E2: 660000 | F2: Cheltuieli curente | G2: Direcția Generală Logistică | H2: =_xlfn.XLOOKUP(G2, Direcții!B:B,Direcții!A:A, "NU GASIT",0) -> 10
A3: 304 | B3: Rechizite | C3: Rechizite | D3: Furnizare - Contract | E3: 25000 | F3: Cheltuieli curente | G3: Direcția Generală Logistică | H3: =_xlfn.XLOOKUP(G3, Direcții!B:B,Direcții!A:A, "NU GASIT",0) -> 10
A4: 305 | B4: Dispozitive de distrugere a documentelor | C4: Rechizite | D4: Furnizare - Contract | E4: 350000 | F4: Cheltuieli curente | G4: Direcția Generală Logistică | H4: =_xlfn.XLOOKUP(G4, Direcții!B:B,Direcții!A:A, "NU GASIT",0) -> 10
A5: 306 | B5: Rechizite - Hârtie pentru fotocopiatoare | C5: Rechizite | D5: Furnizare - Contract | E5: 190000 | F5: Cheltuieli curente | G5: Direcția Generală Logistică | H5: =_xlfn.XLOOKUP(G5, Direcții!B:B,Direcții!A:A, "NU GASIT",0) -> 10
A6: 307 | B6: Echipamente de birou cu excepția mobilierului | C6: Rechizite | D6: Furnizare - Contract | E6: 571735 | F6: Cheltuieli curente | G6: Direcția Generală Situații de Urgență, Statistici și Strategii | H6: =_xlfn.XLOOKUP(G6, Direcții!B:B,Direcții!A:A, "NU GASIT",0) -> 9
A7: 308 | B7: Dispozitive de distrugere a documentelor | C7: Rechizite | D7: Furnizare - Contract | E7: 1829 | F7: Cheltuieli curente | G7: Direcția Generală Situații de Urgență, Statistici și Strategii | H7: =_xlfn.XLOOKUP(G7, Direcții!B:B,Direcții!A:A, "NU GASIT",0) -> 9
A8: 309 | B8: Calculator de birou | C8: Rechizite | D8: Furnizare - Contract | E8: 710 | F8: Cheltuieli curente | G8: Direcția Generală Situații de Urgență, Statistici și Strategii | H8: =_xlfn.XLOOKUP(G8, Direcții!B:B,Direcții!A:A, "NU GASIT",0) -> 9
A9: 311 | B9: Stații grafice cu licențe și accesorii | C9: Stații servere și echipamente de procesare | D9: Furnizare - Contract | E9: 400000 | F9: Cheltuieli curente | G9: Direcția Generală Logistică | H9: =_xlfn.XLOOKUP(G9, Direcții!B:B,Direcții!A:A, "NU GASIT",0) -> 10
A10: 312 | B10: Calculatoare portabile | C10: Stații servere și echipamente de procesare | D10: Furnizare - Contract | E10: 500000 | F10: Cheltuieli curente | G10: Direcția Generală Logistică | H10: =_xlfn.XLOOKUP(G10, Direcții!B:B,Direcții!A:A, "NU GASIT",0) -> 10
A11: 313 | B11: Laptop | C11: Stații servere și echipamente de procesare | D11: Furnizare - Contract | E11: 14622 | F11: Investiții | G11: Direcția Generală Situații de Urgență, Statistici și Strategii | H11: =_xlfn.XLOOKUP(G11, Direcții!B:B,Direcții!A:A, "NU GASIT",0) -> 9
A12: 314 | B12: Calculator PC all in one, sistem de operare win 11, office, antivirus | C12: Stații servere și echipamente de procesare | D12: Furnizare - Contract | E12: 41152 | F12: Investiții | G12: Direcția Generală Situații de Urgență, Statistici și Strategii | H12: =_xlfn.XLOOKUP(G12, Direcții!B:B,Direcții!A:A, "NU GASIT",0) -> 9
A13: 318 | B13: Surse de alimentare neîntreruptibile (UPS) | C13: Echipamente IT | D13: Furnizare - Contract | E13: 50000 | F13: Cheltuieli curente | G13: Direcția Generală Logistică | H13: =_xlfn.XLOOKUP(G13, Direcții!B:B,Direcții!A:A, "NU GASIT",0) -> 10
... A300: 667 | B300: Servicii de cazare la hotel pentru deplasarea în Croația... | C300: ECOALITY: Tineret și Autorități Locale împreună pentru justiția de gen și climatică | D300: Servicii | E300: 7541 | F300: Alte surse | G300: Direcția cultură, Învățământ, Turism | H300: =_xlfn.XLOOKUP(G300, Direcții!B:B,Direcții!A:A, "NU GASIT",0) -> 23

Sheet Buget
A1: An | B1: Venituti_totale | C1: Cheltuieli_totale | D1: Subvenții
A2: 2005 | B2: 1461898.5 | C2: 1460061.3 | D2: 16030.38
A3: 2006 | B3: 1918538.9 | C3: 1823204.5 | D3: 11449.776
A4: 2007 | B4: 3068343.3 | C4: 2972817.8 | D4: 285155.54
A5: 2008 | B5: 3378425.8 | C5: 3273707.9 | D5: 234318.17
A6: 2009 | B6: 3418746.9 | C6: 3322608 | D6: 189675.72
A7: 2010 | B7: 3416388.7 | C7: 3251784.7 | D7: 138090.1
A8: 2011 | B8: 3284054.4 | C8: 3322608 | D8: 88889.97
A9: 2012 | B9: 3201298.8 | C9: 3360123.4 | D9: 26746.106
A10: 2013 | B10: 3206870.6 | C10: 3214449.9 | D10: 31435.521
A11: 2014 | B11: 3394594.5 | C11: 3344321.5 | D11: 117341.55
A12: 2015 | B12: 3595357.3 | C12: 3376090.4 | D12: 73663.27
A13: 2016 | B13: 3715911.8 | C13: 3030891.5 | D13: 69440.675
... A21: 2024 | B21: 6478669.6 | C21: 6593533.4 | D21: 728341.08

Sheet Statistici descriptive
A1: Număr_angajați | C1: Salariu | E1: Valoare contracte(lei) | G1: Valoare achiziții(lei) | K1: Număr_angajați | L1: Salariu | M1: Valoare_contract(lei) | N1: Valoare_achiziție(lei)
J2: Q1 | K2: 22 | L2: 15989 | M2: 43118.225 | N2: 7462.5
A3: Mean | B3: 44.571429 | C3: Mean | D3: 17538.732 | E3: Mean | F3: 458875.03 | G3: Mean | H3: 89111.584 | J3: Q3 | K3: 69.25 | L3: 20429 | M3: 1660817.1 | N3: 294754.68
A4: Standard Error | B4: 6.3405199 | C4: Standard Error | D4: 215.85673 | E4: Standard Error | F4: 171496.53 | G4: Standard Error | H4: 7963.4188 | J4: IQR | K4: 47.25 | L4: 4440 | M4: 1617698.9 | N4: 287292.18
A5: Median | B5: 28 | C5: Median | D5: 15989 | E5: Median | F5: 77000 | G5: Median | H5: 25890 | J5: Lim.sup. | K5: 140.125 | L5: 27089 | M5: 4087365.4 | N5: 725692.96
A6: Mode | B6: 23 | C6: Mode | D6: 15989 | E6: Mode | F6: #N/A | G6: Mode | H6: 2000
A7: Standard Deviation | B7: 33.550877 | C7: Standard Deviation | D7: 2393.967 | E7: Standard Deviation | F7: 822468.45 | G7: Standard Deviation | H7: 137700.38
A8: Sample Variance | B8: 1125.6614 | C8: Sample Variance | D8: 5731077.8 | E8: Sample Variance | F8: 6.7645435e+11 | G8: Sample Variance | H8: 1.8961395e+10
A9: Kurtosis | B9: 0.44037065 | C9: Kurtosis | D9: -0.40164891 | E9: Kurtosis | F9: 3.1786603 | G9: Kurtosis | H9: 5.1969413
A10: Skewness | B10: 1.0753133 | C10: Skewness | D10: 0.35589915 | E10: Skewness | F10: 2.0740716 | G10: Skewness | H10: 2.2765899
A11: Range | B11: 121 | C11: Range | D11: 14554 | E11: Range | F11: 2832320 | G11: Range | H11: 693560
A12: Minimum | B12: 6 | C12: Minimum | D12: 9596 | E12: Minimum | F12: 7680 | G12: Minimum | H12: 100
A13: Maximum | B13: 127 | C13: Maximum | D13: 24150 | E13: Maximum | F13: 2840000 | G13: Maximum | H13: 693660
A14: Sum | B14: 1248 | C14: Sum | D14: 2157264 | E14: Sum | F14: 10554126 | G14: Sum | H14: 26644364
A15: Count | B15: 28 | C15: Count | D15: 123 | E15: Count | F15: 23 | G15: Count | H15: 299

Sheet PivotTable1
A1: Direcția_inițiatoare | B1: (All)
A3: Sum of Valoare(lei) | B3: Column Labels
A4: Row Labels | B4: Alte surse | C4: Cheltuieli curente | D4: Investiții | E4: Grand Total
A5: Furnizare | C5: 1745180.5 | D5: 81100 | E5: 1826280.5
A6: Furnizare directă | C6: 1745180.5 | D6: 81100 | E6: 1826280.5
A7: Furnizare - Acord cadru | C7: 660000 | E7: 660000
A8: Furnizate | C8: 660000 | E8: 660000
A9: Furnizare - Contract | C9: 5190630 | D9: 111224.9 | E9: 5301854.9
A10: Echipamente IT | C10: 281000 | D10: 55450.9 | E10: 336450.9
A11: Materiale personalizate | C11: 1544134 | E11: 1544134
A12: Pachete și licențe software | C12: 1326222 | E12: 1326222
A13: Rechizite | C13: 1139274 | E13: 1139274
A14: Stații servere și echipamente de procesare | C14: 900000 | D14: 55774 | E14: 955774
A15: Lucrări | C15: 686054.84 | D15: 415494 | E15: 1101548.8
A16: Lucrări directe | C16: 686054.84 | D16: 415494 | E16: 1101548.8
A17: Servicii | B17: 172705 | C17: 3302801.1 | D17: 2175263 | E17: 5650769.2
A18: Achiziționare autobuze electrice necesare îmbunătățirii transportului public de călători | D18: 239443.26 | E18: 239443.26
A19: Achiziționarea de vehicule nepoluante pentru transportul public | D19: 4500 | E19: 4500
A20: ECOALITY: Tineret și Autorități Locale împreună pentru justiția de gen și climatică | B20: 172705 | E20: 172705
A21: Extinderea și reabilitarea infrastructurii de apă și apă uzată în zonele Ghidigeni, Oltenitei, Cheile Turzii și Henri Coandă | D21: 1025858 | E21: 1025858
A22: Înnoirea parcului de vehicule destinate transportului public prin achiziția a unui număr de 22 de troleibuze cu emisii zero sau cu baterii | D22: 7100 | E22: 7100
A23: Modernizarea și dotarea liniilor de tramvai | D23: 499102.76 | E23: 499102.76
A24: Reabilitarea sistemului de termoficare | D24: 155500 | E24: 155500
A25: Servicii directe | C25: 3302801.1 | D25: 203173 | E25: 3505974.1
A26: Sistem ITS integrat Smart&Green Mobility | D26: 40586 | E26: 40586
A27: Servicii - Acord cadru | C27: 379917.76 | E27: 379917.76
A28: Servicii de consultanţă în materie de deşeuri | C28: 190000 | E28: 190000
A29: Servicii de urbanism | C29: 189917.76 | E29: 189917.76
A30: Servicii - Contract | B30: 35679 | C30: 9734460.4 | D30: 1953853 | E30: 11723992
A31: Alte servicii | C31: 1138972.3 | E31: 1138972.3
A32: Servicii de asigurare | C32: 1639779 | E32: 1639779
A33: Servicii de brokeraj şi servicii conexe titlurilor şi mărfurilor | B33: 25890 | E33: 25890
A34: Servicii de colectare a deşeurilor | C34: 247680 | E34: 247680
A35: Servicii de consultanţă în materie de deşeuri | C35: 126051 | E35: 126051
A36: Servicii de curăţenie şi igienizare | C36: 1674275.7 | E36: 1674275.7
A37: Servicii de formare | C37: 215233.61 | E37: 215233.61
A38: Servicii de gestionare a tranzacţiilor financiare şi servicii de case de compensare | B38: 9789 | E38: 9789
A39: Servicii de închiriere, amplasare şi întreţinere a toaletelor | C39: 4800 | E39: 4800
A40: Servicii de mentenanță preventivă | C40: 1040656.8 | E40: 1040656.8
A41: Servicii de programare şi de consultanţă software | C41: 285000 | D41: 270000 | E41: 555000
...

Sheet PivotTable2
B3: Total contracte | C3: Total valoare(lei)
A4: Jan | B4: 4 | C4: 1691592
A5: COMPANIA NATIONALA POSTA ROMANA SA | B5: 1 | C5: 200000
A6: FIP CONSULTING SRL | B6: 1 | C6: 1180000
A7: GLOB STAR TRAde SRL | B7: 1 | C7: 42192
A8: LIBRO EVENTS SRL | B8: 1 | C8: 269400
A9: Feb | B9: 2 | C9: 24360
A10: PRIME TELECOM S.R.L. | B10: 1 | C10: 8640
A11: VODAFONE ROMANIA S.A. | B11: 1 | C11: 15720
A12: Mar | B12: 4 | C12: 3088680
A13: Asocierea Alpha Bank România S.A., Banca Comercială Română S.A., BRD – Groupe Société Générale S.A și Raiffeisen Bank S.A. | B13: 1 | C13: 2840000
A14: Centrul Teritorial de Calcul Electronic S.A. | B14: 1 | C14: 7680
A15: CORES ELECTRONIC SRL | B15: 1 | C15: 46000
... A33: Grand Total | B33: 23 | C33: 10554126

Sheet PivotTable3
B3: Total achiziții | C3: Total Valoare(lei) | D3: Total procent
A4: Direcția Generală Logistică | B4: 82 | C4: 7993496.6 | D4: 0.30000704
A5: Cheltuieli curente | B5: 81 | C5: 7723496.6 | D5: 0.28987356
A6: Investiții | B6: 1 | C6: 270000 | D6: 0.010133475
A7: Direcția Generală Servicii Publice | B7: 11 | C7: 3383896 | D7: 0.12700232
A8: Cheltuieli curente | B8: 5 | C8: 1522538 | D8: 0.057142967
A9: Investiții | B9: 6 | C9: 1861358 | D9: 0.069859353
A10: Direcția Generală Situații de Urgență, Statistici și Strategii | B10: 70 | C10: 3342223.8 | D10: 0.12543831
A11: Cheltuieli curente | B11: 62 | C11: 2997238.9 | D11: 0.11249054
A12: Investiții | B12: 8 | C12: 344984.9 | D12: 0.012947763
A13: Direcția Generală Investiții | B13: 9 | C13: 2562736.1 | D13: 0.096183046
A14: Cheltuieli curente | B14: 8 | C14: 2522150.1 | D14: 0.094659797
A15: Investiții | B15: 1 | C15: 40586 | D15: 0.001523249
... A54: Grand Total | B54: 299 | C54: 26644364 | D54: 1

Sheet PivotChart2
A1: Direcția_inițiatoare | B1: (All)
A2: Obiectul_contractului | B2: (All)
A4: Row Labels | B4: Procent
A5: Alte surse | B5: 0.0078209412
A6: Cheltuieli curente | B6: 0.81439531
A7: Investiții | B7: 0.17778375
A8: Grand Total | B8: 1

Sheet PivotChart1
A3: Sum of Valoare(lei) | B3: Column Labels
A4: Row Labels | B4: Alte surse | C4: Cheltuieli curente | D4: Investiții | E4: Grand Total
A5: Direcția Relația cu Ong, Sindicate și Patronate | B5: 0 | C5: 0.00010133475 | D5: 0 | E5: 0.00010133475
A6: Direcția Patrimoniu | B6: 0 | C6: 0.00040468484 | D6: 0 | E6: 0.00040468484
A7: Direcția Juridic | B7: 0 | C7: 0.0013135986 | D7: 0 | E7: 0.0013135986
A8: Direcția Auditul și Managementul Calității | B8: 0 | C8: 0.0022068457 | D8: 0 | E8: 0.0022068457
A9: Serviciul Sănătate și Securitate în Muncă | B9: 0 | C9: 0.0034528879 | D9: 0 | E9: 0.0034528879
A10: Direcția Managementul Resurselor Umane | B10: 0 | C10: 0.010004857 | D10: 0 | E10: 0.010004857
A11: Direcția Guvernanță Corporativă | B11: 0 | C11: 0.011484605 | D11: 0 | E11: 0.011484605
A12: Direcția de Presă | B12: 0 | C12: 0.013144619 | D12: 0 | E12: 0.013144619
A13: Direcția Generală Economică | B13: 0 | C13: 0.01531656 | D13: 0 | E13: 0.01531656
A14: Direcția Generală Administrație și Relații cu Cgmb | B14: 0 | C14: 0.0020642264 | D14: 0.013698957 | E14: 0.015763184
A15: Direcția de Mediu | B15: 0 | C15: 0.019636549 | D15: 0.0037909331 | E15: 0.023427482
A16: Direcția Transporturi | B16: 0 | C16: 0.030963397 | D16: 0.00043536412 | E16: 0.031398761
... A25: Grand Total | B25: 0.0078209412 | C25: 0.81439531 | D25: 0.17778375 | E25: 1

Sheet PivotChart3
A1: Tip_contract | B1: (All)
A2: Sursă_finanțare | B2: (All)
A4: Row Labels | B4: Count of ID_achiziție
A5: Direcția Transporturi | B5: 5
A6: Direcția Generală Investiții | B6: 9
A7: Direcția de Mediu | B7: 9
A8: Direcția cultură, Învățământ, Turism | B8: 11
A9: Direcția Generală Servicii Publice | B9: 11
A10: Direcția Generală Management Proiecte cu Finanțare Externă | B10: 14
A11: Direcția Guvernanță Corporativă | B11: 30
A12: Direcția Relații Externe și Protocol | B12: 33
A13: Direcția Generală Situații de Urgență, Statistici și Strategii | B13: 70
A14: Direcția Generală Logistică | B14: 82
A15: Grand Total | B15: 274

Sheet PivotChart4
A1: Row Labels | B1: Count of ID_contract
A2: Jan | B2: 4
A3: Feb | B3: 2
A4: Mar | B4: 4
A5: Apr | B5: 1
A6: May | B6: 7
A7: Jun | B7: 1
A8: Aug | B8: 3
A9: Sep | B9: 1
A10: Grand Total | B10: 23

Sheet Pivotchart5
A3: Row Labels | B3: Total valoare(lei) | C3: Total achiziții
A4: Direcția Relația cu Ong, Sindicate și Patronate | B4: 2700 | C4: 2
A5: Direcția Patrimoniu | B5: 10782.57 | C5: 3
A6: Direcția Juridic | B6: 35000 | C6: 1
A7: Direcția Auditul și Managementul Calității | B7: 58800 | C7: 1
A8: Serviciul Sănătate și Securitate în Muncă | B8: 92000 | C8: 1
A9: Direcția Managementul Resurselor Umane | B9: 266573.05 | C9: 4
A10: Direcția Guvernanță Corporativă | B10: 306000 | C10: 30
A11: Direcția de Presă | B11: 350230 | C11: 3
A12: Direcția Generală Economică | B12: 408100 | C12: 4
A13: Direcția Generală Administrație și Relații cu Cgmb | B13: 420000 | C13: 4
A14: Direcția de Mediu | B14: 624210.35 | C14: 9
A15: Direcția Transporturi | B15: 836600 | C15: 5
... A24: Grand Total | B24: 26644364 | C24: 299

Sheet CB_DATA_
A1: Crystal Ball Data
A3: Workbook Variables | B3: Last Var Column | C3: 0
A4: Name:
A5: Value:
A7: Worksheet Data | B7: Last Data Column Used
B8: 2
A10: Sheet Ref
A11: =CB_DATA_!#REF! -> #REF! | B11: =Buget!#REF! -> #REF!
A13: Sheet Guid
A14: 1289f067-b401-48b4-b17b-5b2e6fe7f371 | B14: f98baf5d-6a10-4b42-b2a6-7b303273e036
A16: Deleted sheet count
A19: Last row used
A20: 28 | B20: 31
A25: Data blocks
A26: CB_Block_0 | B26: CB_Block_11.1.1000.0:1
A27: 㜸〱敤㕣㔹㙣㈴㐷ㄹ㥥㙡捦㡣愷挷昶摡㔹㙦㡥つ㈱㌱攴㈴㕥㥣昵㈶㑢〸戰㉣㍥戲㐷昰慥㥤戵㜷〳〲㌴摢㥥愹㕥㜷㜶扡摢改敥昱慥㐳愴㐴㄰㉥㜱㠹㔳〴挲愱〸㈱㈱㄰挷㑢〸挷ぢㄲㄲ〸㉤ㄲて昰㠰〴㈸㈰〴て㈰戴ㄲ㉦㍣㜰㝤㕦㜵昷㑣昷㡣愷敤㑣ㄲ㜰㤰㙢㌳扦慢敢敡慡晡捦晡晦敡攴㐴㉥㤷晢㌷ㄲ晦㌲攵㤹戹㙥㜱摤て愴㍤㌱攳搶敢戲ㅡ㔸慥攳㑦㑣㜹㥥戱㍥㘷昹㐱ㅦㅡㄴ㉢ㄶ敡晤㐲挵户ㅥ㤶愵捡㥡昴㝣㌴㉡攴㜲愵㤲慥愱㥥㠳昰㌷ㄲ㍦攸散㌵㤸〷㔸㥡㤹㥥㕦㝥㄰愳㉥〶慥㈷昷㡤㥤〹晢ㅥ㥡㥣㥣㤸㥣㌸戸晦敥〳ㄳ晢昷㡤捤㌴敡㐱挳㤳㠷ㅣ搹〸㍣愳扥㙦㙣愱戱㕣户慡㙦㤶敢㑢敥㜹改ㅣ㤲换晢敦㕣㌶敥㝡敤攴㕤〷て㥡昷摣昳摡㐱扣㍡㜷㜲㘶㝡挱㤳愶晦〲㡤㔹攰㤴敦㥡㤵㔵㡢㙢㤳搲戳㥣㜳ㄳ㌳搳昸㉦㌱㝦㍣摤㍤戱戸㈲㘵挰㔷㑢㑦㍡㔵改敢攸㌸㘰㑦昹㝥挳㕥攵收改昶ㄱ㉣戵㙡昸㐱挱㥥㤱昵扡㙥挷愳㤶散㜹散㕤摤㔸ㅦ戴ㄷ愵攳㕢㠱戵㘶〵敢㐵㝢〹〳搵㠶散搳扥㍣㘵㌸攷攴㐹挳㤶〵晢㘸挳慡攵挳㤴敢扢㌵ㅥ㈲㌹㌱戵晣㠹㈹摦㥥㔹㌱㍣㌵㈳㥦ㅢ㤳搱昶㠸㔷㑤户扤戱晢戸㥣扡㝡〳挷扣戹㝢㍢搴㥣㌱扣㘶换昱敥㉤愳挵愷㘷㜰㐷昷昶㠹㍤㑡昷㜹㔵昷㍥㙡㉢搳慤挵㐰㐴摦㙡㐷戱ㄸ扤㐸搰㑦㔰㈲㈰〲昵㌲挱〰挱㈰㠰挸晦つ㕣㤲散挸㉡慤㘲㘸㤵㘵慤㔲搵㉡㌵慤㈲戵㡡愹㔵捥㘹㤵ㄵ慤㘲㘹㤵〷戵捡㜹戴㠹㔳愹扦㕦㡢搲挷晥昸戵慦㕦㉡摦㌴晢搵摦晥收㡡戹㝦捥晦㙢㜰ㄷㅡ摤ㅦ㑤㙡搶㌳㉥㠰搴㕡㔴っ㡥攰扦捤戹〲㑣㘱ㅥ㌴敦㌶㈷㈷㙢〷昷ㅢ㜷ㅡ〵㉥㉢〳昹㈹㐲ㄹ㐱摢㐱昳〱换愹戹ㄷㄴ敥慥㥢㌶㝣搹摡戸昱愸㙥摡㙤㌸㌵晦㘵ㅢ㔷㉥〶㐶㈰慦㙤慦㙢つ搲搱㙤ㄱ㙣㈵㝤昵扥敢摢扢㥤㌱敡つ㌹㜵搱ち慢㕦摥㔶㙤㉦㜸敥㜲昷摡㈳㥥㝣愸㔹摢㌱愳㈹〸戵㌵㌵㜶挷㉡挳慡㜰㕥㘳㌳㉢慥㉦ㅤ㌵扤㜱㝢挱慡㥥㤷摥愲愴㐸㤴㌵戵搴㉢㔹ㄵ㜱晤昸扣㠳㠵㠲㕢㙢慦㑣㤶㥡昷㕥っ挰捣戲㠶昹慥㑡㉦㔸㕦㌲㤶敢昲慡㔴㤳昰㥤愸搸㥢㉡㍥攲㔶ㅢ晥㡣敢〴㥥㕢㑦搷㑣搵搶っ㐸㥡摡〹户㈶昳昹㥣ㄲち㄰戸㝤㝤㐲攴㙥敦捥ぢちㄱ〹ㄴ㤳㤱慦㐹㤳摤挴㈹慣づ慢愸㑢搲愴㜶搳㈶㠳㜱扥㑡挶㘴㜰㘰㘲㑤搴ㅦ㝣改㙤㥢っ摢挴摣㡢摢㔸搳㐶愳搵摦扢㈶㥤攰㤸攱搴敡搲换搴㝥㠲㌳搲㠷〱ち㤷㈱㄰扡敥ㅥ㔵㥤戸㈸搶ぢㄷ慣㕡戰㔲㕣㤱搶戹㤵〰㘵搰㤰愵ㄲ户戶㈳改㔷愰㐸摦㑤㌰ち㔰㉥攷㡡㝢搸愸㔸㐶捡ㄵ㈸㥤㌲㜸㌹㈵挸搹㉦挵换㠳收ㄱ慢ㅥ挸㔰㈸て㥢挰㐸愸搵ㄴ晡㠶㐸愲㥥㔱つㄵ挶ㅥ㜳〶㔴㙡㔸㑥戰摥攲摢づ㉥〹㠹㘸㐷ㄶ㙣㍢㔹㐰㔱㤰㤶〷ㄹ扣〶愲㘹㤳〶搹㡤ㄳ㐴㐴㌶挸搰散ㄸ㌹㑤㘴㙣㥦㈱㈳搰㍥㐹㠴㙣扤扦扢㡣㈰戱㜷ㄲ㈹㍢㜵攵挷ㅤ㘹戶㤱㉤ㅦ㑡戳㉢戱㜱晡㔵〴㔷ㄳ㕣㐳戰ㄷ㐰晣ㄱㄲ㡥㔲づ昹㜴搲㕦㠶㘷晤㍡㠲㤷〳㐰㍥改㤴㌹㤱愸愲つ戵ㄵ㍢㤲敤㠶㘰㈷㉢愳㌸ㄴ㐵戴㡣㥢㜶收㤰慤㄰ㅤ㔹㥤摢㐳搷收㤵㡥扤愵㍢㙤㈶㤷㐳㡡捣㘸㥡㕣敢㈶㑤㤳ㅢ挱愶㍤敡慤ㅢ搰㔵ㅦ㈳㜸〵㐰㔹㝦㈵㈱㤴ぢつ摥慤㔹昴㌴㈹㕦ㄲ㘶㔱㘸っ昵愸攰㈳㐲收ㄱ㈰㐳挸㜵ㅣ㕦㜶㙣㘸㥡㠳攳收㑢摥㠶摥搷㥤扦㈳愴户改捤ㅤ扤㐳㝦搱㜳戴愲㙦〴㝢㠹㕦㜷搵㌱㌷愳㕡扦㠵攰㔶㠰㌶ㅤ挳搳昷㜳昵ㄴ㈸戳搸㑥㘰㙥㌷扤㉥捡捡㕤㕡㕦㤵㑡〳つ㥡㑢㠶㜷㑥〶昰㘰ㅣ㥦㠵㉤散㝡㥥慣攳㔰㕢㔳〵㍣扦㕣㥤㉥昴㡦㜸慥捤昲ㅤㅢ搹㝦㐹㈸㠶㝣㕥敢换戵搹挸ㄹ戶㘶挲攷㤴愰ㅣ敡攰㍢扢ぢ㠹㐴愷㌴㜹戱㕦昶昹㜲㐷㤲昴㈰㐹㕥㠵㙤搵㙦〷㠰㤴㄰扦散㉡㔱昶戱搹慢㔵戳戴挵㑡て㕦挶改愴捤㠷搸㈱㐷〶㐲㠷敤㌴晣〷晥㤰扤㘸搹㑤㘱㌱㘰㉦㐸慦ち摦㠲㔵㤷攵搰㉤㑢㔱戳㈳㉢㕥㈲戲愲慦慦攳㍣㥤攱㕦㔳㜴搲㈶㈵㌲戹㍤戳㌲攳㉣摥㈲㉡扡㈱㈹㔴㌲㕣㐳㑤〹㐴捡㘳摢ㅤㄱ搳㠳㠸戹〳ㅢ愷敦㈷㤸㈴㌸〰㔰昸ㄹ㈴捤㔶㌷㥥攱戰晥㌵扡戴㉢㤵㕣㠹㘸㔰㉥挲㑢㕤㠵搵㐱扥收㌵〴㜷〳戴㤹㍦㜴㐰㘶㄰愲㐲㜹㠲㄰㔵ㄸ挳㍣㘳挹ぢ愴㠱㕤㈶〲㑢㌳つ㍦㜰㙤㐶㤶㠶捣㔹昷愴ㅢ捣㕡晥㉡㈲㔱愳㘶㤴㜹㘰㐵㍡愰㉥て戶㑦㕢㤹扢扡㉡㙢扡戹攸㌶㈰摡㡥捦㙥㠷㠳㌹戶〳戶愴㍡㥢㙢〲愹户昳㌱㠶㄰搸㘹攵㙦愵㌷㜶㑢摥㙦ㅥ晡㠶㕢㍢扡㘴〵㜵㌹㘰㠶㑣挷㝣挹挴㉥㈲㜲㔰敢㌷㤷㔶㍣㈹㘷㠷捣愳㥥㔵慢㕢㡥㈴㌲㘰㘳㌲㔸㌷㈷捦㈱㑡戰攰㌲〶攸㍡㐳收㤲㘷㌸晥慡挱㠰攲晡敥搴㤳ち㡢ㄴ捣㘹换昱昱ㅡ㠵㐵收㠷捤挵ㄵ昷〲㈲戶つ摢㌹㙡慣晡摢〲㉢㈴晡㌰㈹搴〸㑤㘸㥡㈸㘹愵㕥昱挳〳㜹㉥㐷摥换ㄳ㈸㕣攵ち昴㤹㘷㘸㙦摡昵㔱㡣㠶㜶㍡攷㌴㠸攸㔱戳戰㉦㔳ち㤳㔳昵㝢搸攷㜵〰昷ㅤ㍤㝤扣ㄵ㤹㝢㕥㌱敢〲扤晣ㄹ㌲㕥㤱㐵㌳㄰㐲ㅦ摤慥㤰㔴㔸㐶捡〱〷〲攳㝣㙡㈷扦戲愹摡㤰晡㜶戵戲㐷㄰㐹ㅡ㌴攷㡣㘵㔹㐷㍣摡㌶㠲㕤攱〳捤㔸摢愸晢㔱摤㡣㙢摢〶㐹㡢㘴戹㔸㌵㐸挱㔳㡤挰㍤㘱㌹扡〹愰攸㉦㉡㌲㉥愲挸戸愸㡡〶捤㔳っつ慡㍣挷㜲捦ㄹ㥥ㄵ慣搸㔶戵挴〷㠶敦戶〵㑤㠲挹㈹㜹攳ㄴ换㡣戱㌶㙢晥㌴㑣㌶㝦〲攸㥥㠰ㅣ攵搶ㄱ晤愰㕣㑤ㄴ昱㑦昴攸㔸㠲㠰㔱㥥㔲晤つㄸ慤愰㙥㐷㐰攴愸㜴㌹扥㠳㜱昹㔱㤴㠴㐲㠸㔸捦㈰ㄱ㜸〵ㄳ㐲㥥㉥敥愲㜹摡戱〲㘰㡦ㄸ㍢㘲〵戳㍥㔰づ㠰慣㍡摥㕥慢戰㥡攸㌴摥搴ち㌷㜴㔶愵搴挴昵㥤昵㐹扤㜱搳〶搵愱㐶㐹㈸㤲捤ㅡ㈹捤戲挱ㅣ户㤳慡ㄱ㑡㜱挷摡㐶㘴戹㑤㕢晢㑥㈹昲㍣ㄴ㤳愲㤹㥣晥㐶㐵㈸〸昴㐶㍡㡡㍥晢㙣昲㐸㐴㙣㘸〳㤴愹愷挲戲愱㈸㈴㜸ㅣ搷㑥㙡戲ㅣ㍤㠱扦㜷㐵搹昹㐶㤰慡㌱㉥㡥㐶㌵㔳昵晡扣〳㉢愱㙡㜸戵㙤挲搲㔸㕢愸㘱ㄴ㜷昶慡晤挳敤㑤㌰㘲挴㠶っ㡢㘴昸㠱挱㠶㘰慥㐴㐴㤵搶搹㄰户扡㔹㕣攲搳〹㘹㌸ち〳㡢㐱㙤㔶慥㈹㌳慣㘵挹㡦慡づ捤搳愲㤲愳扡㌹戵散㐳愵〷㤴攳㔱㑥㌱戸㙥㥥愲㕢ち㤷ㄸ㈰㜶愳摣㐲㌵㐰㘸户㌹〰㑦〶摢〷㍢搸㤱㌰㜴㐲敢㡣ㄲ戴㤸㐱戸改㐵㤰㜷㝡挴㈸〴愹愹搲㕦て㡢捦㍥挱昴搵挳戹㌸ㄳ㌱ㄱ挳㕤ㄹ搶〳㤰㥢㡣㑣㤲㡢㐶攳㠰㜹㈸搹㤴搰ㅡ㡣换㘸㘲っ搱攴昳〲摣攲㘱㉣㙢㤸㙣㔳挷㍤户挰㠲㌶慤慦敦㌲㡦㍢搵㝡愳㈶㤵㉡㡥㘵戵搲挸摢〲㕦敡ち㘰挸㑤ㄹ晢ㄲ㙤捡㜱ㅣ愵戸㘴㈲愹㜷扢㕢㍦㡣敥㑡挸㘱㡣㔰昵㌱〰㤹攱㤶㔳〱戱㡥㝢ち戴て㜷户㉥㌰愸换㜳㄰㘹ㅤ㐵㤴㘵㜳戸㡦搷㡣㈲㉢㙥㑢㌴㥢㜳攷㕣摡散㠹愲㘳㔶㔸戴㉤㜰㠴㜵㠶〲慦㔸㠴㌱搲㈳㜷㜰㤰摣攵㈸扡㝢昹㔱昵㤸扢っ㔴㈸っ〸挶㜸㜹ち捡㘱㔷挱㐸㌴戸戵㤶搵㉤ㄸ晤愵攵慤㑦〱〸㠶㠱㘹搰愲㘵㘸攰捣㈰扦戹㠱㜳〳㕡㘵㐴㐸㤳挱㔴挶㈸㐷攱戰〷搲挰㑤㍣㐸㉦戹㔰㐲挱ㅥ㜵㌱㉣扥㥢㌸㙥攳〸攴㝡㔷戵ㄵ㉥ㄸ〱慥扦㌸㝢摢㡡愷㙡㌵㥡扢昰捦㙤ぢ慣攲敡㐶㘸㡥敥㘹扢㤴愵搶㐴晢敥挶戶㡡攸戲攰㠱搹㠹㘳㐶㔰㕤㔹っ搶挳㡢㕢扤㤲㐴攱〷昰㐷㙣昸㜶摡捣㜹㠷ㄷ㔱搷戸昷攵昳㡥㝢挱㔱昳㉡昸扣昵〷ち挱ㄵ捡㝥㑥戲㥣晢㌷晥愹愴攵ち摦挷㠸㕢㤹㌶〷㘸㌹㐸㌸㡥㑡愱㌴ㄸ㐳㍥㠳㑥㘰扢㌷㙦つ㤰㑥昶戴搱㠹ㄲ〴㍢㠴攲㥣㝢挱〸㐵㝣て㘸㈵戱㠴㐷㜲散昹㔷挰晡攲扢㈸㈱挲昱ㅣ㠹㤱挲㉢㤰换㐰㥤ㄲ攴搱ㄵて㕥〸昹晦挱㔲捣捤ㅢ戲搳㝦㠱㤹挵㌳敤㈸扡㥥㈸晡㑥〷㡡〴慦㠱㈸晥扤て㤹㌸ㄵㄸ㥥㝤㑥㠱㜰慥㘹攷〰晡愲㕦昸晤ㅦㅥ㐰攷㈲攲㔰㌶ㅡ㐲㙤㌷攳戹㘹㈲昴㜵㤸〸っ摥㉢ㄳ攱〴㌲㠲㔱晣搰㐴㠸㝣㈰昳㈸搸摣㐴㘰㙣㉦挳㄰㑣㠴㕡ㄳ㙥つ㥥挰慥戲改ㅦ㍢㠶㡢户搲㐷㍣ㅦ㑡换㥦㠱㐷敡敡捥攲〵挳㌳散扤慡晣愸㈷愱捣扣㈵摣攴㔶㕤搸攳摡つ㙢㔴愷つ㝣ㄵ戱㤷㝤挷㥦戲戵晢敢挰㔴㤸㐲昷扤㈸㠹攲昳昰㤴〸㥥ㅢ㜲敦摣昳㡤愳扦㝢昸昱挳扣慤ㄶ搱㙡攱㜶攴㝢〹搹搳㥥㐰㔰㌷㜱㔱攴㑡㝥㤸㜳〲㥦㈸㔹慢㜵㌹㙤㜸捡ち昲㜵㍢捥㠶㠴㤷㈰捣㤰昸戶㠳㠹㠹㝢て愱㠹㌹搱收敥㔴ㅦ㌶㈹ㄷ攱㐴㘲攲捡愷ㄷ㠷つ㐵㔷㐵搶愳戵㔹昸ㄶ㔴搱㜳㥣㐸摡㑡攴愹㤳㐹㠸㙦戶敢扡㠳搴㜵攱㐱㠶㘱晦㔸㑡㈱晥㐰ち㐹ㅥ㘴㜸㈱㐰㐹愹㔳挸ㄴ敥〰挸㠸慣戵㠷㜸改て搸ㄱ〲戲㜹改慦挷㡦㔸戰㡢挰㘲散㡢敦昵㐴㑢㕢㌴㔶㑤っ搵㉡㥢㘶ㄱㄹ㜵㜸㘱挱㘴㕣㥡戲㜴づ愰㜴换敥㈸扥㘴挸づ〳㙦㈱㘳ㄷ㙣晡摡捡昶扤㑥〳㌷㍦愰㘷㡡㑡㘱㌸扢㔹㡣〳愹㡡搱㠵㑤换㘱ㄱ攱㜰㤸㙤㜶ㅡ㠸慡愰戳㥣扤㌸㤵㈲昸挷㉦㠵㔸㍦摥ㅡ晡捡昶ㅡ敡㌸愷ㅦぢ攴て昶搷昵ㄹ㡣㡤户㤲㘳㈰㘱户搴慡ㄴ㕥て㍦㡤㉥㕣㜴㑥攸慤慣㝡ㄶ〷昱㈷收慣㍥慤㐳晦㌳㝡慤㌸敢っ㝢㌳㡣㥤搲晦㙦㐱挱愶晡㕦㌰昶愶㄰昹搶㈸挳㠷〲攳㈷㥢㠶㙣戸㈳昰㙣㈳㜸愳づ挶扡捡㌲攴ㅤ收ㄶ昱昱㙡㔸慤㈴㌸晣㕥昹昶慢ㄱ捤扥戴㙤〷扡ち㐰挶㠶ち㕦㠱〸敡摡㍦㉤户攲搳㙤昱㙤攸戸攷㠴㔵昵㕣摦㌵㠳戱㐵〴㝤挷昸敤㤹〹㥢㘷㑡㝣戹㕤愸摤㠸㥤ㄸ㝣〷晡㥣㥣㠷挰㍥㈹㠳ㄷ㉡ㄶ挹挸挲搶㈲ㄹ晣づ㘹㈴ㄱ㕥愲㜶昰慦㌰敦㙦ㄸ㜵㝣扡㍡て㕦㘷挰愲㙤愱散㐲㡦㜳晢つつ㙥ㅤ敥㘸扤ㄹ晥㈰㔹㥦㐰㜰㑣㉤攱㙤敦攰扥戶敦㐱扡㙤戴㌶㥦㉤㝢昳戹㤵ぢ㑦〱愷㕢㝢㑢㥡㘴昸㑥㝥㤱㕣搶㉢㠴戸戴㝦ㄸ㝦户敥愰攵㘸愳愰昳攸㠳㙥㍡挲挶敢㜰㥦㙤㈱晡㝤ㄶ㕤挵ㄴ〱㝥扡ㄱ㘵昸㈰攸攵㈳㉢㡡㉦㘰㔹㘴〰攴㜳挵㉡㐰㜷慡㝥㜲㈳慡ㅥ㠹〵戲攰ㄹ㠳攴㔸ㄶ㥦㐳㐳㙥㔷戸㙣戰〴㤷㉤搴㔹〲㜹㍤敥㠱㝣㑥昰㉣愱㈶昲ㄹ㜴㘸㑥挴㐲㘹昷㠹㝣㝡愳㠹〸㕡〱㙡愱挹昱㐷㘲㉤愲搷㔱慤摢〴づ㠱ぢ㌰㑣戱㐸㔹㔳っ㐳ぢ摦㈵㘶㤰㝥ㅥ晤㝤昶昰捦㉥㌱晤攵戰㔰㠲㄰㔵改挹㔳㄰慡挹㝦㌴㌹㜹て愵摤㈷晦攱㡤㈶㍦㐲ㄹ挹㤹攸〱挰㔰㥦愸攰㡦㕡㑣〳ㄹ敥㈳㝦攲㉣〱㝥愹㔹㡣ㄸ㈸㔱㝤㉦㈰㠳扥摣㜰搵敡㈲㌲㜱摦〲搷㥦昱㜱㡦戲㡦㜸ㄱ㤲扥㥣㘲攸㡣㉤㠶㕡戱㘴㐷㕥搸㙤㈱ㅢ戰㈴㝥㉤摢㔵愴ㄷ㝢㡣昰㡢昷挵㠸㌹㜶㉣晥㜲㑡㡢㘲㑥㈰㡣搰㈲㈵晤㜰㈳挵㝢攳挶摦㝥扡攵㌲㐵〵ㄲ愸㈷㙣㑣㍡㔳㡤摦ㄳ㌷㍥㠰慦戲㔴㥢ㅣ㙦㄰㌰㍤ㅢ㌷㈶㍤慡挶㡦挷㡤晦㝣㘰㙦戳㜱㑣㠷攱挸〵ㄲ㐹㠶慤慢慣晦挴ㄷ摡挳㘸㕥㌰愹㍦〷捣戰㤸㤲㔳㠵㡥敢㑡㠳づ攲㌲㠸㠷㙦愴攷㜰户〹㔷㐰㈰㘴挳晦㔵挲㜱摣㜹㥡㌵〲〳㥦㐰慦㈱搸散改敡㠹㥤㡢收扣㠷㠲㝥昳戸㡦㌳㔵㙤㕢㤱〸捣㠱㝣戸扦㥢㌸攵㌳㑣挷搶㝥挴㐱㌲㡤㜷㐸㝡㔳ㅥ㉡戰㤲ㄷ敦㡡㌱㥢㝢慣㐵㌳晡愳㐰づ愴㈳㈰㌳晡㘳㠰㘱㈰㠶户㤵㜳㈳攴㝦挵摣敦㘲挵扢〹ㅥ〷㈸ぢ㌲㍢改愰昸ㅥ㠰攱昸㝦㔴㌱戶愶晣㈵㥡㜸㌸㝥㔹㤲㡣昴昷戱挳晢〱晡攰扥ㄵㄱㄱ㤶昵て愰㈴昹㔲ちづ昵搲て戲攲㐳〴ㅦ〶㈸ㄷ㌸搹㉤敦ㅡ搷搴愳收晡〸扡㡡挷〸昰搳㍦ㅡ㘵昸㔰攰㍥扣扥扢慤捣愳㜰晣㘱㍦㐲㥤愹㉦昸敦挵ㄷ昹敢㕣㜴ㅦ晥㠷㈴〵㘵搸攷戵搷昵㌶ㄶ㤹㠰㌶戹晡慤㘲戳㥦挷㌸㕣㔷㉢㠲挲ㄱ愹㔴㑡㕡㔱㄰摦㕣戰㜰昱〶扥攵㤰慡㄰㠲㌴愰㉡㥣愸攲㌰ち昴㑦戰㈹㜱㑣㍣改㥦攴ㄳ㔱慢㌶昱㔳㔱㠶て㠲㜸㔵摤ㅦ㡣扡挷㉦㈴慥㔵㠵搵昶㐲攲㕦㔵慣㈴㕦昸〴〷㔳挸㐲㈶慤㤵㠸㌴㐵㐳㥦㐳㘶愸㙦㤸㜳㝢〰㍦敤愲愸㥥慤㥤㍤晢昷攱晣搸戵昹户扣㘹昰㠹㘷㝦晡晢㡦晦攲敤㠷晥昴㡦㈷㥦晣挵ㅦ㍥㝥改ㅦ㍦㔸㍥昴攳愷㥥晡搱㝤㕦扣昴晢摤收㤷戴愷晦㍥昷愵㐷㈶捦㍦昲㤰㜹晡昶愳㡦扣昵挱晢㈷ㄷ慥ㄸ敦敢敢敦扦㜵昴㈷搷摣㌶昲搸㐳捦㠸ㅦ晥敡㙡㐷愸攵攲〵改㘹㜰搹㙡ㅡ㥦㐷〶搳攰㡣㕦搴㘹㜰戹㙡愳㤶愳㡤㥡㐶㐱〹㍥つ㑥㐰㔵ㄸ改㡡㠱晦〰㌸搹戴㔲 | B27: 㜸〱戵ㄸ㕢㙣ㅢ㔹㜵挶慦㡣㥤愴㜱㤲扥ㅢ挰㡢㤲㉥㙤ㄲ攳㘷ㅣ户㉡挵戱搳挴㙤㥤㤷搳㤶ㅦ㜶㜲㘷收㍡㥥㜴㍣㤳㥤ㄹ㠷㠴㕤㘹㉢扥昶ぢ愱㐵㐲挰㐲㡢㤰昸㐱〲搴㑤㤱㜶㔹〹㠴㠴㔶㉤㙡〹㉣㤵㘰ㄱ㡢昸〰昱㔸㈴㜶挵㔳攲愳㥣㌳昶搸㥥挴昵㉡散㜲ㄳ㥦戹昷摣昳扥昷㥥㝢㘶ㄸ㤶㘱㤸㐷搰昰㠹捤㠳㥤愱攲㤶㘱搲㑡㌸慢㈹ちㄵ㑤㔹㔳㡤㜰㐶搷挹搶㘵搹㌰摤㐰攰攳㘵㤸㌷扣扣㈱㝦㥡㜲晣〶搵つ㈰昲㌲っ挷昹㕤㌰㡦㐲昰ㄷ戴〷㝥攴敡昱〰㔸捥㑥捤ぢ㙢㈰戵㘸㙡㍡ㅤぢ㕤慤昱㥥㡢㐶挳搱㜰㌲㤲㡡㠵㈳㘳愱㙣㔵㌱慢㍡㍤愷搲慡愹ㄳ㘵㉣戴㔰ㄵㄴ㔹扣㐴户㤶戵敢㔴㍤㐷㠵㐸㕣㈰㠹挹㘸㈲㤹㉣愵搳㤳㍤愰㥡㤹换㑥㉤攸戴㘴扣㑦㌲扤㘸㜲㌲㐷㐵ㄹ㝤愳㔴㤷搵搵㜰㜶ち晥㕢散て㠳㐶㐹ㄶ挱㤵昰㝣ㄱ晢挵㌲愵㘶㌷㜰㜶昳㔶搷戲攸〰㍦扤㈹㔲㈵㑢ㄵ㘵〹っㅣ攰㈱戰搵㡡㍡慦换㔴㌵〹挶搷捦㤷㠹㤱㈳㈶㌵扡戱㌷㑢㠹〴㜱ㄹ攴慤㈰㐹㌵昲㈲㤸㐰㡤㘰ㅤ户愴㝤慡㠶㜰ㄲ㑤㙦㠰挸㔶愲ㅡ愲户㜲挵愰㑢㐴㕤愵㜳愴㐲扤㤵㤹慡㉣㜹㜰㌹摣㉥㤷㡢㜱㡦户㜳搳㌲扤改㘰搳ㅤっ㜶戴ㅤ㐷㙢㘰戲㔳愹戰挳㙢搴挶戲㙣扢扤㌵㑢㡣戲㐹〴㠵戲摤昵㥤㘷搹〷っ㝥ㅦ㠲慥ㅡ慢㥦㠳㘷㈰㄰㘰㍣晦㠲ㅤ摢㑡㡡〱㜷昱挴挵ぢ㉥㕥㜴昱㤲㡢愷㉥扥攴攲㔷㕤㝣搹挵换㉥㝥捤挵㕦〷ㅡ扢㜱㕤㕤攰户搵㘶㥥㜸㙢㈷昳敡敦㉦扥㥡㝤㈷昲敤㙦慣扣搰ㄳ〰愲㠵散搴㉣㔵搶㘱〹摥慦捤㠴㝥散㉦捡㘱攰ㄸ攰㤷攸慡㑥つ摣㠱〵㙡㤶㌵〹昶挷〲散〳㑤㕡摥㕡愷㍤㝣㤱ㄲ㐳㔳㠹㈲㥢㕢〷昸ㅡ㐵戱㤰挹㔴㑤慤扦㌹慣㌱ㄸ㌶㐱捥㐹〰挳㕤〴挵改㈲㑡攸戳㈵挰㔰㔹㉦㤳〶扦㜳㍡户㜷㝡㡡㥡㈴㔸攷捥㉤捦ㄵ昹㔶㠳㙡〸ㄴ攸㈰㐱ㅥ㕢愳㐵戲㔰㤶㝢㙤ぢ㉣㡦㙣晤挵㡣挳㥣㘲㘶㠶㔴㉡つ敢㘶慦㔹挴戶㈸ㅣ戶ㅡて攳㔶㑤㌰戴戸ㅢ㥡ち㘸㙡㐳㔳挱挱㕢㉣散搲㘴ㄱ㌷㌵㌹愹㘷慦ㄵ㥣㥡㙡摣㌶㜹㙥㌹㘳㠵愵ㄹ〴ㄸ愳愵慤〴捥㐰㘶㜸㠷㝥㤴〰㐱㙡搲ㄷ㜶〹㠴戱㔳㘰㠱㜷ち㉣散ㄶ㔸愸〹挴ㄸ㔴㈰㉦㠹㤹愵㝣㈱㜳〸ㄳ〱搵愹㉡㔲㘳㜴㕥捤㤶㌱㡤㐸ㅦ㙥挵㤶愶㌷㑤慡㑡㔴㕡搰㌵㌸㌵收搶㌲㥥收挳づ㤲っ㕣㈴ㅢㄴ㈶㡥㌹搰ㄷ㌴戱㙡㘴㌵搵搴㌵挵㌹㤳㤱㌶〸攸㤴ち㥡㐴ㄹ㉢㔹搹挷户挳搳敤㘶㔹㠶㍤摤㉥㍢搵㑦㜴戸㜹㝥愶搵㙡〵㡦晢㘸㈷昲㤶㈳㠶㘷づ改㔹づ晥㝣慣て晦昷㍥㙡㘸ㅦ㍢㔸捦㘵㔶〶㥥㈵慡愴㔰扤㕤昶㙢摣慣㉣㈶㔶挶晢て㐸㙥晢㜰〰敦搹慥つ愲㔴㈹捦㌳ㅣ㥡攷㐷㈹㝦〷㈹晢昱㙢慦ㄸ㤰〲〹ㅢ㠱㜵㡢㝦昹㑢搸㕥㌹捦摡ㅤ晢戹〷昱搸㠹晦〷愵慤捣㝥㍥㔶㐷㠳㈰攰敦〵愷攰ㅡ昱攲扤戲晦㡢っ愳攱户㙥㔰愸㐷っ㙦攵㠲愶ㅢ㙥㜷扢㤵㙤摣㙢ㅤ㈷昱㘲昴ㅦ㐰搰〷挰㠳㤷㕣㐷㝡戴㍡㜰㔹㈳搲〵㠲㠵㐷㔷扤㠲攲戲㕡㘵㥤攸㔴て愲摡㉣ㅣㅡ㌸㡣ㅢ㌲搴ㄱㅣ㈲㡡㔰愹㜹搰㘰摦㔵摣㉢〶㕣晤㙥挶敢敤收摡改捡摢戲㠶摢㔴㠲昹㍤昲晦戲㌸㜹ㅥ扤〸〴搰㌶㝦㄰㐱㍦〰ㄶ〳㡤㍢挸㍦㔰敦㔸摢〹㝤㐵㉦㤱つㄱ㠱〰㤶㕡晥㐱〴〷〱戰ㄸ㠷㌶〴㠷㤰攰㌰㠰㈰㙡㐰㠵ㅣ㠷㥣ㅣ㠷㑢挲㜱㈸㡢㐳㍥㈶㠸摡慤戸ㅥ㠱㡥晦㈸㠲㘳〸㡥〳〸愲㌱搶攴〹攸昴扡㠳愸ㄸ㜹㝤㐳〰㐶戲㔳搹㈵㍥ㄲ㡢㑢㤱搲㘴㉣㈹㑤㐰㡤㔹㑡㤳搸㐴㍣ㄱ㑤㑥〸㠹戴㈰㐵攳㈴㘸搹〹攴晥て〰〸愲㘵㈸挱晦㐱ㅣ愱㠹搶〸攷扣㘸挱挹捥〹〶敢扡㍣ㄴ搴㈸愶㡦㥦戹㤲捦挱扤㉦㙡㔰㔶㔳挹㙢㡤愱攰㠶昴扡改攵㔵㈸摦扡㜸㔵㠳㕡㤱昴㔸挸㜵㑣扣慡挹昱㜴㔳㔴慡ㄲ昵昰ち㔹㍤挰㑢摡㥣㘶挲搶愴㈲㌱㑣㐷愱搰捤攷つ㍢愹昵㌵㉡㠸㕡㔶㍣挰㕦〶昲〵㑡慥攷㔱摦㤱挶㜴㠱愸㔵愲捣㠳㐹㍡㙣愹㝥㍥㈳慤㔵㤱㔰ㄷ㐱户慣搰㐱㈷挶摡㘳〷敢㌸摢ちぢ搹㔳㐷㉥㘹㔵㔵戲攵㔸〳㙢㝡挰㥥愶㠶愹㐳㘱㕤㤰搵㍤㈸戲〹攱挵〰搷㤶ㄱ搷ㄲ㤷ㄳ㜲㌲ぢ扦晤㈴扤㕡㌲攷搸㐸愷昵搹敤慡㝤ぢ昸㝣ㅤ㔵搵搸㉣捦㙣づ捥攷㐳㡤㡣㉦〴㈰㐴㠴㜸㈲㐹挴愸㤴㑥㠹〹㤱㤶㐸㍣㐵㘹㌴㐵愳改㜴㈴㤵㑡挶㉣捡㈷㄰㕡㔹ㄸ㥦扦㠱愴㡥㠹ㅤ㤱捤收㝤ㄳ㔰晢㜶〱〳攸扣㌷㥡ㄲ㝦㝢摥敥㝢㝦晤㙥昷挸㉥㍦㍢㠹㐵愱㙦搷㡤㝦晢㌹ㄶ㡦㈵㥥づ挶㌷〲㈰㤴㡣挵愸㤸㠸搱㔲㘴㈲㤵㈰㈴㥡ㄶ㔲㄰ㄹ㤱㈶攳搱㔴ㄴづ㈲㑡昶㥤〴搰㜷㤵慡戲㔹㌵㘵摥搴㑣愲㔰㐰㔹㡤㝤㘳㜷㜸㘰晣㠸㘱㝦〹㄰㐳㘴搳㌱㑣搳㍦昶ㄷ㌰㠱㍥摡㤳户摥昹收搹㤱慦㝥攷㔱晤昹ㅣ㡢㜹愳㘶攵㘹攸㠵〴㤲㡥〹ㄲ㥤ㄴ㤲㌴㥥㠸㑣㑣〸㤳㐲㉣㤲㉥搱㔲㐲㠸㑥愶㔳㘹㑣㐵扥㔱〰晤搹㌲㠵户㔸㤹㉡つ㍢搱〳㘸散㐳搰攷㔸㐶ㄸ㠳㥤㍦〷昸㔸㍢㕦㠷挹㔶㍢㙢愲㕡愲㠹愹慤㘶攷㐷愱ㄷㄲ愴㜸㑣㡣㑥挴㈶搲改㠹㐴㈹㈹㄰㜱㈲ㄶㄵ挴㘴㘴戲㤴ㄲ㈶攳㘹㑣㥣扥〸㠰㐰戱㉡挰㑢攳摤ㄷ㘵㤹戱つ摣〱㘵㙤っ晣㐹㈷〳ㅦ扣㡢㠱㕥捣戶㘷摢ㅤ㌴慣〷つ㝣搱㙣㔴㤹扢换挹㘹㈸て户㌰戲㙥戸挱扣㔶愲昰戸捥晣㙦戲昰㌰㘲愱㘵晤敥㠳搱敦㐱㡥㜳戳愳挴㍣晣晣㐹ㄴ㡦挹扦敤愱散昴㤶㡣慦㠹㠷㉡㜹㘳〹㘳㘱㉣㙢㤹挶㍢㝢扦攵㌵攰㐷敤搲㘳愴㠹挹〸〶㝣㔱㌰愹捤㌶慦㌷昸㝡㥢㔴㤰㠷て㌵㐷㔸㜳搳㑤ㄳ㉦㤲ㄳ㑤㙣㕥㌵愰㝥愷㤲㉤搱㠰攴攳㜱戹搹㡦戵ぢ㜶慢㈷戰㝣㝢㍦㠴㡣摡㥦㍣㌰㍦㥦㘸㔳㑢㑣挹愶㔵晥㕡昹摢㡦昷慦㉦〵愰晢摣㜰㘶㌸㝡㘶㌸㌷ㅣ㡢㝡敦挲ㅡ扤㐷昵捥㜵㐲㘵搸〲晥㌴㐰ㄶ敦㙣搴㠱愸㍥㕣扡㍦挳捦戵挹㡡㉢搲捡捡扦晢㍣愱攳㥥捤㉦摥挸摤搸晥晣捣摡㕣㘶㙤昱昶㘷愷㡥㝥敥晥晤㥤敤㘴攲㘱晣㘱ㅣ扥㔹扤ㅥ晦改攲㝡昸挱愹㔳攳ㄷ扦晢攰搲昸昸愹㡢昷㝦戶挸㝤愴昰攳㝢㤷晦㌹昷慤㥥㝢㍢㜳て戶ぢ㠵㔸㘴敥㘲攲㜶〴捡㠸挲昶㥤㍢㉢散戱ㅦ摣㠸扥晣搲换挳挹㙢㍢改昳㑦㍥㤹㝣挵㔳㕥扢㝤昳㤹戵愷搶ㄶ㑢㉦摤㥣㉦㍤㥤晦っ㌱敦㕣㕡搳㑦摥晤晥昲搷捡㑦㝤敦收昶㘰㌰昳收搷晦昰愱愱扦ㅥ晤摤㥦摥晡攳㡢户㕥〸摣ㄹっ㘷㐶㘶㕥㝢㉤收晥攴扤挳户晣愶ㄸ扤晥散搳愵㉢愷㘷㥥㍤昶愳晦㡣昵昴晣㉡㜷㜶晣捣攱㠳捦てつ㝤㈵昴户㡦摦㌸昲晣ㅢ㍦ㅣ晡㐴㘴扢㍣㔰㌹㝥㜷㑣㘵扥㜰昳㤹㕥て㐶愱搳攲㘰慡攸慡昰〴扦〰㜲ㄵ㕥愱敡慡㔹㙥㝣昵㠳㤲㡦㠳捦㝥㘷㠰挸づ㙣ㅦづ㌰收㔶㌱搶晤㕦挷晣㑦搶
A28: Decisioneering:7.0.0.0 | B28: Decisioneering:11.1.1000.0
B29: CB_Block_0
B30: 㜸〱敤㕣㔹㙣㈴㐷ㄹ㥥㙡捦㡣愷挷昶摡㔹㙦㡥つ㈱㜱〸㈱㠷ㄷ㘷扤挹ㄲ〲㉣㡢㡦散ㄱ扣㙢㘷敤摤㠰㌸㘶摢㌳搵敢捥㑥㜷㍢摤㍤摥㜵㠸㤴〸挲㈵〸㤱戸㜳㜰㈸㐲㤱㜸攱㤴㈰ㅣ㉦㐸㐸㐱㈸㐸㍣挰〳ㄲて〱㈱㜸〰愱㤵㜸攱〱〹扥慦扡㝢愶㝢挶搳㜶㈶〹㌸挸戵㤹摦搵㜵㜵㔵晤㘷晤㝦㜵㜲㈲㤷换晤ㅢ㠹㝦㤹昲捣㕣戳戸敥〷搲㥥㤸㜱敢㜵㔹つ㉣搷昱㈷愶㍣捦㔸㥦戳晣愰てつ㡡ㄵぢ昵㝥愱攲㕢て捡㔲㘵㑤㝡㍥ㅡㄵ㜲戹㔲㐹搷㔰捦㐱昸ㅢ㠹ㅦ㜴昶ㅡ捣〳㉣捤㑣捦㉦摦㡦㔱ㄷ〳搷㤳晢挶捥㠴㝤て㑤㑥㑥㑣㑥ㅣ摣㝦攷㠱㠹晤晢挶㘶ㅡ昵愰攱挹㐳㡥㙣〴㥥㔱摦㌷戶搰㔸慥㕢搵㜷换昵㈵昷扣㜴づ挹攵晤户㉦ㅢ㜷扣㜵昲㡥㠳〷捤扢敥㝡敢㈰㕥㥤㍢㌹㌳扤攰㐹搳㝦㠵挶㉣㜰捡㜷捣捡慡挵戵㐹改㔹捥戹㠹㤹㘹晣㤷㤸㍦㥥敥㥣㔸㕣㤱㌲攰慢愵㈷㥤慡昴㜵㜴ㅣ戰愷㝣扦㘱慦㜲昳㜴晢〸㤶㕡㌵晣愰㘰捦挸㝡㕤户攳㔱㑢昶㍣昶慥㙥慣て摡㡢搲昱慤挰㕡戳㠲昵愲扤㠴㠱㙡㐳昶㘹㕦㥥㌲㥣㜳昲愴㘱换㠲㝤戴㘱搵昲㘱捡昵摤ㄴて㤱㥣㤸㕡晥挴㤴㙦捦慣ㄸ㥥㥡㤱捦㡤挹㘸㝢挴慢愶摢摥搰㝤㕣㑥㕤扤㠱㘳摥搸扤ㅤ㙡捥ㄸ㕥戳攵㜸昷㤶搱攲搳㌳戸慤㝢晢挴ㅥ愵晢摣搲扤㡦摡捡㜴㙢㌱㄰搱户摡㔱㉣㐶㉦ㄲ昴ㄳ㤴〸㠸㐰扤㑣㌰㐰㌰〸㈰昲晦〰㤷㈴㍢戲㑡慢ㄸ㕡㘵㔹慢㔴戵㑡㑤慢㐸慤㘲㙡㤵㜳㕡㘵㐵慢㔸㕡攵㝥慤㜲ㅥ㙤攲㔴敡敦搷愲昴攴〷㙢捦㝦㘹昸㉢㈷扦户敦昶㘷慦㝢散晢捦っ敥㐲愳㝢愳㐹捤㝡挶〵㤰㕡㡢㡡挱ㄱ晣户㌹㔷㠰㈹捣㠳收㥤收攴㘴敤攰㝥攳㜶愳挰㘵㘵㈰㍦㐵㈸㈳㘸㍢㘸摥㘷㌹㌵昷㠲挲摤㌵搳㠶㉦㕢ㅢ㌷ㅥ搵㑤扢つ愷收扦㙥攳捡挵挰〸攴搵敤㜵慤㐱㍡扡㉤㠲慤愴慦摥㜷㙤㝢户㌳㐶扤㈱愷㉥㕡㘱昵敢摢慡敤〵捦㕤敥㕥㝢挴㤳て㌴㙢㍢㘶㌴〵愱戶愶挶敥㔸㘵㔸ㄵ捥㙢㙣㘶挵昵愵愳愶㌷㙥㉦㔸搵昳搲㕢㤴ㄴ㠹戲愶㤶㝡㌹慢㈲慥ㅦ㥦㜷戰㔰㜰㙢敤つ挹㔲昳敥㡢〱㤸㔹搶㌰摦㔵改〵敢㑢挶㜲㕤㕥㤱㙡ㄲ扥ㄳㄵ㝢㔳挵㐷摣㙡挳㥦㜱㥤挰㜳敢改㥡愹摡㥡〱㐹㔳㍢攱搶㘴㍥㥦㔳㐲〱〲户慦㑦㠸摣慤摤㜹㐱㈱㈲㠱㘲㌲昲㔵㘹戲㥢㌸㠵搵㘱ㄵ㜵㐹㥡搴摥戸挹㘰㥣慦㤲㌱ㄹㅣ㤸㔸ㄳ昵〷㕦㝡昳㈶挳㌶㌱昷敡㌶搶戴搱㘸昵㜷慦㐹㈷㌸㘶㌸戵扡昴㌲戵㥦攰㡣昴㘱㠰挲㈵〸㠴慥扢㐷㔵㈷㉥㡡昵挲〵慢ㄶ慣ㄴ㔷愴㜵㙥㈵㐰ㄹ㌴㘴愹挴慤敤㐸晡㘵㈸搲㜷ㄳ㡣〲㤴换戹攲ㅥ㌶㉡㤶㤱㜲〵㑡愷っ㕥㑥〹㜲昶㑢昱昲愰㜹挴慡〷㌲ㄴ捡挳㈶㌰ㄲ㙡㌵㠵扥㈱㤲愸㘷㔴㐳㠵戱挷㥣〱㤵ㅡ㤶ㄳ慣户昸戶㠳㑢㐲㈲摡㤱〵摢㑥ㄶ㔰ㄴ愴攵㐱〶慦㠱㘸摡愴㐱㜶攳〴ㄱ㤱つ㌲㌴㍢㐶㑥ㄳㄹ摢㘷挸〸戴㑦ㄲ㈱㕢敦敦㉥㈳㐸散㥤㐴捡㑥㕤昹㜱㐷㥡㙤㘴换㠷搲散㜲㙣㥣㝥〵挱㤵〴㔷ㄱ散〵㄰㝦㠶㠴愳㤴㐳㍥㥤昴搷攱㔹扦㠶攰昵〰㤰㑦㍡㘵㑥㈴慡㘸㐳㙤挵㡥㘴扢㈱搸挹捡㈸づ㐵ㄱ㉤攳愶㥤㌹㘴㉢㐴㐷㔶攷昶搰戵㜹愵㘳摦搴㥤㌶㤳换㈱㐵㘶㌴㑤慥㜵㤳愶挹㡤㘰搳ㅥ昵搶㜵攸慡㡦ㄱ㕣て㔰搶摦㐰〸攵㐲㠳㜷㙢ㄶ㍤㑤捡搷㠴㔹ㄴㅡ㐳㍤㉡昸㠸㤰㜹〴挸㄰㜲ㅤ挷㤷ㅤㅢ㥡收攰戸昹㥡户愱昷㜵攷敦〸改㙤㝡㜳㐷敦搰㕦昴ㄲ慤攸ㅢ挰㕥攲昷㕤㜵捣㡤愸搶摦㐴㜰ㄳ㐰㥢㡥攱改晢愵㝡ち㤴㔹㙣㈷㌰户㥢㕥ㄷ㘵攵㉥慤慦㑡愵㠱〶捤㈵挳㍢㈷〳㜸㌰㡥捦挲ㄶ㜶㍤㑦搶㜱愸慤愹〲㥥㕦慥㑣ㄷ晡㐷㍣搷㘶昹㡥㡤散扦㈶ㄴ㐳㍥慦昵攵摡㙣攴っ㕢㌳攱㜳㑡㔰づ㜵昰敤摤㠵㐴愲㔳㥡扣搸㉦晢㝣戹㈳㐹㝡㤰㈴户㘰㕢昵㕢〱㈰㈵挴㙦扢㑡㤴㝤㙣昶㘶搵㉣㙤戱搲挳㤷㜱㍡㘹昳㈱㜶挸㤱㠱搰㘱㍢つ晦㠱㍦㘴㉦㕡㜶㔳㔸っ搸ぢ搲慢挲户㘰搵㘵㌹㜴换㔲搴散挸㡡搷㠸慣攸敢敢㌸㑦㘷昸搷ㄴ㥤戴㐹㠹㑣㙥捦慣捣㌸㡢户㠸㡡㙥㐸ち㤵っ搷㔰㔳〲㤱昲搸㜶㐷挴昴㈰㘲㙥挳挶改晢〹㈶〹づ〰ㄴ㝥〵㐹戳搵㡤㘷㌸慣㝦㡤㉥敤㑡㈵㔷㈲ㅡ㤴㡢昰㠵慥挲敡㈰㕦昳ㄶ㠲㍢〱摡捣ㅦ㍡㈰㌳〸㔱愱㍣㐱㠸㉡㡣㘱㥥戱攴〵搲挰㉥ㄳ㠱愵㤹㠶ㅦ戸㌶㈳㑢㐳收慣㝢搲つ㘶㉤㝦ㄵ㤱愸㔱㌳捡摣户㈲ㅤ㔰㤷〷摢愷慤捣㕤㕤㤵㌵摤㕣㜴ㅢ㄰㙤挷㘷户挳挱ㅣ摢〱㕢㔲㥤捤㌵㠱搴摢昹ㄸ㐳〸散戴昲户搲ㅢ扢㈵敦㌷て㝤挳慤ㅤ㕤戲㠲扡ㅣ㌰㐳愶㘳扥㘴㘲ㄷㄱ㌹愸昵㥢㑢㉢㥥㤴戳㐳收㔱捦慡搵㉤㐷ㄲㄹ戰㌱ㄹ慣㥢㤳攷㄰㈵㔸㜰ㄹ〳㜴㥤㈱㜳挹㌳ㅣ㝦搵㘰㐰㜱㝤㜷敡㐹㠵㐵ち收戴攵昸㜸㡤挲㈲昳挳收攲㡡㝢〱ㄱ摢㠶敤ㅣ㌵㔶晤㙤㠱ㄵㄲ㝤㤸ㄴ㙡㠴㈶㌴㑤㤴戴㔲慦昸攱㠱㍣㤷㈳敦攵〹ㄴ慥㜲〵晡捣㌳戴㌷敤晡㈸㐶㐳㍢㥤㜳ㅡ㐴昴愸㔹搸㤷㈹㠵挹愹晡㕤散昳㌶㠰㝢㡥㥥㍥摥㡡捣扤慣㤸㜵㠱㕥晥っㄹ慦挸愲ㄹ〸愱㡦㙥㔷㐸㉡㉣㈳攵㠰〳㠱㜱㍥戵㤳㕦搹㔴㙤㐸㝤扢㕡搹㈳㠸㈴つ㥡㜳挶戲慣㈳ㅥ㙤ㅢ挱慥昰㠱㘶慣㙤搴晤愸㙥挶戵㙤㠳愴㐵戲㕣慣ㅡ愴攰愹㐶攰㥥戰ㅣ摤〴㔰昴ㄷㄵㄹㄷ㔱㘴㕣㔴㐵㠳收㈹㠶〶㔵㥥㘳戹攷っ捦ち㔶㙣慢㕡攲〳挳㜷摢㠲㈶挱攴㤴扣㜱㡡㘵挶㔸㥢㌵㝦ㅡ㈶㥢㍦〱㜴㑦㐰㡥㜲敢㠸㝥㔰慥㈶㡡昸㈷㝡㜴㉣㐱挰㈸㑦愹晥づ㡣㔶㔰户㈳㈰㜲㔴扡ㄴ摦挱戸昴㌰㑡㐲㈱㐴慣㘷㤰〸扣㠲〹㈱㑦ㄷ㜷搱㍣敤㔸〱戰㐷㡣ㅤ戱㠲㔹ㅦ㈸〷㐰㔶ㅤ㙦慦㔶㔸㑤㜴ㅡ㙦㙡㠵敢㍡慢㔲㙡攲摡捥晡愴摥㜸攳〶搵愱㐶㐹㈸㤲捤ㅡ㈹捤戲挱ㅣ户㤳慡ㄱ㑡㜱挷摡㐶㘴戹㑤㕢晢㑥㈹昲㌲ㄴ㤳愲㤹㥣晥㑥㐵㈸〸昴㐶㍡㡡㍥晢㙣昲㐸㐴㙣㘸〳㤴愹愷挲戲愱㈸㈴㜸ㅣ搷㑥㙡戲ㅣ㍤㠱扦㜷㐵搹昹㐶㤰慡㌱㉥㡥㐶㌵㔳昵晡扣〳㉢愱㙡㜸戵㙤挲搲㔸㕢愸㘱ㄴ㜷昶慡晤挳敤㑤㌰㘲挴㠶っ㡢㘴昸㠱挱㠶㘰慥㐴㐴㤵搶搹㄰户扡㔹㕣攲搳〹㘹㌸ち〳㡢㐱㙤㔶慥㈹㌳慣㘵挹㡦慡づ捤搳愲㤲愳扡㌹戵散㐳愵〷㤴攳㔱㑥㌱戸㙥㥥愲㕢ち㤷ㄸ㈰㜶愳摣㐲㌵㐰㘸户㌹〰㑦〶摢〷㍢搸㤱㌰㜴㐲敢㡣ㄲ戴㤸㐱戸改㐵㤰㜷㝡挴㈸〴愹愹搲摦て㡢㈷㥦㘰晡收攱㕣㥣㠹㤸㠸攱慥っ敢〱挸㑤㐶㈶挹㐵愳㜱挰㍣㤴㙣㑡㘸つ挶㘵㌴㌱㠶㘸昲㜹〱㙥昱㌰㤶㌵㑣戶愹攳㥥㕢㘰㐱㥢搶搷㜷㤹挷㥤㙡扤㔱㤳㑡ㄵ挷戲㕡㘹攴㙤㠱㉦㜵〵㌰攴愶㡣㝤㠹㌶攵㌸㡥㔲㕣㌲㤱搴扢摤慤ㅦ㐶㜷㈵攴㌰㐶愸晡ㄸ㠰捣㜰换愹㠰㔸挷㍤〵摡㠷扢㕢ㄷㄸ搴攵㌹㠸戴㡥㈲捡戲㌹摣挷㙢㐶㤱ㄵ户㈵㥡捤戹㜳㉥㙤昶㐴搱㌱㉢㉣摡ㄶ㌸挲㍡㐳㠱㔷㉣挲ㄸ改㤱㍢㌸㐸敥㔲ㄴ摤扤昴戰㝡捣㕤〲㉡ㄴ〶〴㘳扣㍣〵攵戰慢㘰㈴ㅡ摣㕡换敡ㄶ㡣晥搲昲搶愷〰〴挳挰㌴㘸搱㌲㌴㜰㘶㤰摦摣挰戹づ慤㌲㈲愴挹㘰㉡㘳㤴愳㜰搸〳㘹攰㈶ㅥ愴㤷㕣㈸愱㘰㡦扡ㄸㄶ摦㑤ㅣ户㜱〴㜲扤㉢摡ちㄷ㡣〰搷㕦㥣扤㙤挵㔳戵ㅡ捤㕤昸攷戶〵㔶㜱㜵㈳㌴㐷昷戴㕤捡㔲㙢愲㝤㜷㐳㕢㐵㜴㔹昰挰散挴㌱㈳愸慥㉣〶敢攱挵慤㕥㐹愲昰㔳昸㈳㌶㝣㍢㙤收扣挳㡢愸㙢摣晢昲㜹挷扤攰愸㜹ㄵ㝣摥晡〳㠵攰ち㘵㍦㈷㔹捥晤ㅢ晦㔴搲㜲㠵㥦㘰挴慤㑣㥢〳戴ㅣ㈴ㅣ㐷愵㔰ㅡ㡣㈱㥦㐱㈷戰摤㥢户〶㐸㈷㝢摡攸㐴〹㠲ㅤ㐲㜱捥扤㘲㠴㈲㝥っ戴㤲㔸挲㈳㌹昶晣㔹戰扥昸ㄱ㑡㠸㜰㍣㐷㘲愴㜰㍤㜲ㄹ愸㔳㠲㍣扡攲挱ぢ㈱晦㍦㔸㡡戹㜹㐳㜶晡㉦㌰戳㜸慥ㅤ㐵搷ㄲ㐵㍦散㐰㤱攰㌵㄰挵扦昷㈰ㄳ愷〲挳戳㉦㈹㄰捥㌵敤ㅣ㐰㕦昵ぢ扦晦挳〳攸㕣㐴ㅣ捡㐶㐳愸敤㐶㍣㌷㑤㠴扥づㄳ㠱挱㝢㘵㈲㥣㐰㐶㌰㡡ㅦ㥡〸㤱て㘴ㅥ〵㥢㥢〸㡣敤㘵ㄸ㠲㠹㔰㙢挲慤挱ㄳ搸ㄵ㌶晤㘳挷㜰昱㔶晡㠸攷㐳㘹昹㌳昰㐸㕤搹㔹扣㘰㜸㠶扤㔷㤵ㅦ昵㈴㤴㤹户㠴㥢摣慡ぢ㝢㕣扤㘱㡤敡戴㠱慦㈲昶戲敦昸㔳戶㜶㝦ㅤ㤸ち㔳攸扥ㄷ㈵㔱㝣ㄹ㥥ㄲ挱㜳㐳敥㐳㝢扥㜵昴てて㍥㝡㤸户搵㈲㕡㉤摣㡡㝣㉦㈱㝢摡ㄳ〸敡㈶㉥㡡㕣捥て㜳㑥攰ㄳ㈵㙢戵㉥愷つ㑦㔹㐱扥㙥挷搹㤰昰ㄲ㠴ㄹㄲ摦㜶㌰㌱㜱敦㈱㌴㌱㈷摡摣㥤敡挳㈶攵㈲㥣㐸㑣㕣昹昴攲戰愱攸慡挸㝡戴㌶ぢ摦㠱㉡㝡㠹ㄳ㐹㕢㠹㍣㜵㌲〹昱敤㜶㕤㜷㤰扡㉥㍣挸㌰散ㅦ㑢㈹挴ㅦ㐸㈱挹㠳っ㉦〴㈸㈹㜵ち㤹挲㙤〰ㄹ㤱戵昶㄰㉦晤〱㍢㐲㐰㌶㉦晤昵昸ㄱぢ㜶ㄱ㔸㡣㝤昱扤㥥㘸㘹㡢挶慡㠹愱㕡㘵搳㉣㈲愳づ㉦㉣㤸㡣㑢㔳㤶捥〱㤴㙥搹ㅤ挵㤷っ搹㘱攰㉤㘴散㠲㑤㕦㕢搹扥摢㘹攰收〷昴㑣㔱㈹っ㘷㌷㡢㜱㈰㔵㌱扡戰㘹㌹㉣㈲ㅣづ戳捤㑥〳㔱ㄵ㜴㤶戳ㄷ愷㔲〴晦昸愵㄰敢挷㕢㐳㕦摥㕥㐳ㅤ攷昴㘳㠱晣挱晥扡㌶㠳戱昱㔶㜲っ㈴散㤶㕡㤵挲敢攱愷搱㠵㡢捥〹扤㤵㔵捦攲㈰晥挴㥣搵愷㜵攸㝦㐶慦ㄵ㘷㥤㘱㙦㠶戱㔳晡晦㍤㈸搸㔴晦ぢ挶摥ㄴ㈲摦ㅢ㘵昸㔰㘰晣㘴搳㤰つ㜷〴㥥㙤〴㙦搴挱㔸㔷㔹㠶扣挳摣㈲㍥㕥つ慢㤵〴㠷摦㉢摦㝥㌵愲搹㤷戶敤㐰㔷〱挸搸㔰攱㔹㠸愰慥晤搳㜲㉢㍥摤ㄶ摦㠷㡥㝢㑥㔸㔵捦昵㕤㌳ㄸ㕢㐴搰㜷㡣摦㥥㤹戰㜹愶挴㌷摡㠵摡つ搸㠹挱て愰捦挹㜹〸散㤳㌲㜸愵㘲㤱㡣㉣㙣㉤㤲挱敦㤰㐶ㄲ攱㈵㙡〷晦㌲昳摥㠶㔱挷愷慢昳昰㜵〶㉣摡ㄶ捡㉥昴㌸户摦搰攰搶攱㡥搶扢攱て㤲昵〹〴挷搴ㄲ摥昷〱敥㙢晢ㅥ愴摢㐶㙢昳搹戲㌷㥦㕢戹昰っ㜰扡戵户愴㐹㠶敦攴ㄷ挹㘵扤㐲㠸㑢晢㠷昱㜷敢づ㕡㡥㌶ち㍡㡦㍥攸愶㈳㙣扣づ昷搹ㄶ愲摦㘷搱㔵㑣ㄱ攰愷ㅢ㔱㠶て㠲㕥㍥戲愲昸㉡㤶㐵〶㐰㍥㔷慣〲㜴愷敡愷㌷愲敡㤱㔸㈰ぢ㥥㌱㐸㡥㘵昱ㄴㅡ㜲扢挲㘵㠳㈵戸㙣愱捥ㄲ挸敢㜱て攴㜳㠲㘷〹㌵㤱㉦愳㐳㜳㈲ㄶ㑡扢㑦攴㡢ㅢ㑤㐴搰ち㔰ぢ㑤㡥㍦ㄲ㙢ㄱ扤㡥㙡摤㈶㜰〸㕣㠰㘱㡡㐵捡㥡㘲ㄸ㕡昸ㄱ㌱㠳昴敢攸敦㡢㠷㝦昵〲搳摦づぢ㈵〸㔱㤵㥥㍣〵愱㥡晣攳挹挹㝢㈸敤㍥昹挷㌶㥡晣〸㘵㈴㘷愲〷〰㐳㝤愲㠲㍦㙡㌱つ㘴戸㡦晣㠹戳〴昸愵㘶㌱㘲愰㐴昵扤㠰っ晡㜲挳㔵慢㡢挸挴㝤ぢ㕣㝦挶挷㍤捡㍥攲㐵㐸晡㜲㡡愱㌳戶ㄸ㙡挵㤲ㅤ㜹㘱户㠵㙣挰㤲昸戵㙣㔷㤱㕥散㌱挲㉦㍥ㅥ㈳收搸戱昸换㈹㉤㡡㌹㠱㌰㐲㡢㤴昴挳㡤ㄴㅦ㡢ㅢ㝦昷〷㉤㤷㈹㉡㤰㐰㍤㘱㘳搲㤹㙡晣搱戸昱〱㝣㤵愵摡攴㜸㠳㠰改挵戸㌱改㔱㌵㝥㌴㙥晣搷〳㝢㥢㡤㘳㍡っ㐷㉥㤰㐸㌲㙣㕤㘵晤㈷扥搰ㅥ㐶昳㠲㐹晤㌹㘰㠶挵㤴㥣㉡㜴㕣㔷ㅡ㜴㄰㤷㐱㍣㝣㈳㍤㠷扢㑤戸〲〲㈱ㅢ晥慦ㄲ㡥攳捥搳慣ㄱㄸ昸〴㝡つ挱㘶㑦㔷㑦散㕣㌴攷㍤ㄴ昴㥢挷㝤㥣愹㙡摢㡡㐴㘰づ攴挳晤摤挴㈹㥦㘱㍡戶昶㈳づ㤲㘹扣㐳搲㥢昲㔰㠱㤵扣昸㜰㡣搹摣㈳㉤㥡搱ㅦ〶㜲㈰ㅤ〱㤹搱ㅦ〱っ〳㌱扣慤㥣ㅢ㈱晦㉢收晥㌰㉢㍥㐲昰㈸㐰㔹㤰搹㐹〷挵㡦〲っ挷晦愳㡡戱㌵攵㉦搱挴㠳昱换㤲㘴愴㝦㥣ㅤ㍥〱搰〷昷慤㠸㠸戰慣㝦ㄲ㈵挹㤷㔲㜰愸㤷㝥㡡ㄵ㥦㈶㜸っ愰㕣攰㘴户扣㙢㕣㔳㡦㥡敢㌳攸㉡ㅥ㈱挰㑦㝦㍣捡昰愱挰㝤㜸㝢㜷㕢㤹㐷攱昸挳㝥㠴㍡㔳㕦昰摦㡤㉦昲搷戹攸㍥晣て㐹ち捡戰捦㙢㙦敢㙤㉣㌲〱㙤㜲昵㕢挵㘶扦㡣㜱戸慥㔶〴㠵㈳㔲愹㤴戴愲㈰扥戹㘰攱攲つ㝣换㈱㔵㈱〴㘹㐰㔵㌸㔱挵㘱ㄴ攸㥦㘳㔳攲㤸㜸搲㍦捦㈷愲㔶㙤攲ㄷ愲っㅦ〴昱慡扡摦ㅦ㜵㡦㕦㐸㕣慢ち慢敤㠵挴扦慡㔸㐹扥昰〹づ愶㤰㠵㑣㕡㉢ㄱ㘹㡡㠶㥥㐲㘶愸㙦㤸㜳扢て㍦敤愲愸㥥慤㥤㍤晢捦攱晣搸搵昹昷扣㙢昰㠹ㄷ㝦昹挷捦晥收晤㠷晥昲慦愷㥦晥捤㥦㍥晢挲扦㝥扡㝣攸昹㘷㥥昹昹㍤㕦㝢攱㡦扢捤慦㙢㍦昸攷摣搷ㅦ㥡㍣晦搰〳收改㕢㡦㍥昴摥晢敦㥤㕣戸㙣扣慦慦扦晦愶搱㕦㕣㜵昳挸㈳て㍣㈷㝥昶扢㉢ㅤ愱㤶㡢ㄷ愴愷挱㘵慢㘹㝣〵ㄹ㑣㠳㌳㝥㔵愷挱攵慡㡤㕡㡥㌶㙡ㅡ〵㈵昸㌴㌸〱㔵㘱愴㉢〶晥〳㐳っ戲愷
B31: Decisioneering:7.0.0.0
